<?xml version="1.0"?>

<robot name="differential_drive_robot"
xmlns:xacro="http://www.ros.org/wiki/xacro">

<!-- ############################################################ -->
<!-- Geometry and Constants                                      -->
<!-- ############################################################ -->

<!-- Pi constant -->
<xacro:property name="pi_const" value="3.14159265"/>

<!-- Body dimensions -->
<xacro:property name="a" value="1"/>
<xacro:property name="b" value="0.3"/>
<xacro:property name="c" value="0.6"/>

<!-- Wheel and caster dimensions -->
<!-- Wheel and caster radius -->
<xacro:property name="r" value="0.15"/>

<!-- Wheel width -->
<xacro:property name="d" value="0.1"/>

<xacro:property name="s1" value="${b/2+r}"/>
<xacro:property name="s2" value="${2*r}"/>
<xacro:property name="s3" value="${2*r}"/>
<xacro:property name="s4" value="${c/2+d/2}"/>


<!-- ############################################################ -->
<!--                Mass and inertia                             -->
<!-- ############################################################ -->

<!-- Material density -->
<!-- Body material density -->

<xacro:property name="m1" value="40.0"/>
<xacro:property name="m2" value="2.0"/>
<xacro:property name="m3" value="0.5"/>

<!-- Moments of inertia of the robot body -->
<xacro:property name="Ix_body" value="${(1/12)*m1*(b*b+c*c)}" />
<xacro:property name="Iy_body" value="${(1/12)*m1*(a*a+c*c)}" />
<xacro:property name="Iz_body" value="${(1/12)*m1*(a*a+b*b)}" />

<!-- Moments of inertia of the wheel -->
<xacro:property name="Iz_wheel" value="${0.5*m2*r*r}" />
<xacro:property name="I_wheel" value="${(1.0/12.0)*m2*(3.0*r*r+d*d)}" />

<!-- Moments of inertia of the caster sphere -->
<xacro:property name="I_caster" value="${(2.0/5.0)*m3*r*r}" />

<!-- This macro defines the complete inertial section of the robot body -->
<!-- It is used later in the code -->
<xacro:macro name="inertia_body">

  <inertial>

    <!-- Displacement and orientation of the center of the mass frame of the link with respect to -->
    <origin rpy="0 0 0" xyz="0 0 ${s1}"/>
    <mass value="${m1}"/>
    <inertia
      ixx="${Ix_body}"
      ixy="0.0"
      ixz="0.0"
      iyy="${Iy_body}"
      iyz="0"
      izz="${Iz_body}" />
    </inertial>
</xacro:macro>

<!-- This macro defines the complete inertial section of the wheel -->
<!-- It is used later in the code -->

<xacro:macro name="inertia_wheel">
    <inertial>
    <origin rpy="1.570795 0 0" xyz="0 0 0"/>
    <mass value="${m2}"/>
    <inertia
      ixx="${I_wheel}"
      ixy="0.0"
      ixz="0.0"
      iyy="${I_wheel}"
      iyz="0"
      izz="${Iz_wheel}" />
    </inertial>
</xacro:macro>

<!-- This macro defines the complete inertial section of the caster -->
<!-- It is used later in the code -->

<xacro:macro name="inertia_caster">
    <inertial>
    <origin rpy="0 0 0" xyz="0 0 0"/>
    <mass value="${m3}"/>
    <inertia
      ixx="${I_caster}"
      ixy="0.0"
      ixz="0.0"
      iyy="${I_caster}"
      iyz="0"
      izz="${I_caster}" />
    </inertial>
</xacro:macro>

<xacro:include filename="$(find mobile_robot)/model/robot.gazebo"/>

<!-- We need to have this link otherwise Gazebo will complain -->

<link name="base_footprint">
</link>

<joint name="body_link_joint" type="fixed">
  <parent link="base_footprint"/>
  <child link="body_link"/>
</joint>

<link name="body_link">
  <visual>
    <geometry>
      <box size="${a} ${c} ${b}" />
    </geometry>

  <!-- Displacement and orientation of the geometric center of the link -->
  <origin rpy="0 0 0" xyz="0 0 ${s1}"/>
  </visual>

  <collision>
    <geometry>
      <box size="${a} ${c} ${b}" />
    </geometry>
    <origin rpy="0 0 0" xyz="0 0 ${s1}"/>
  </collision>

  <xacro:inertia_body />
</link>

<joint name="wheel1_joint" type="continuous">
  <parent link="body_link"/>
  <child link="wheel1_link" />
  <origin xyz="${-s2} ${-s4} ${r}" rpy="0 0 0" />
  <axis xyz="0 1 0"/>
  <limit effort="100" velocity="10"/>
  <dynamics damping="1.0" friction="1.0"/>
</joint>

<link name="wheel1_link">
  <visual>
    <origin rpy="1.570795 0 0" xyz="0 0 0"/>
    <geometry>
      <cylinder length="${d}" radius="${r}"/>
    </geometry>
  </visual>

  <collision>
    <origin rpy="1.570795 0 0" xyz="0 0 0"/>
    <geometry>
      <cylinder length="${d}" radius="${r}"/>
    </geometry>
  </collision>

  <xacro:inertia_wheel />
</link>

<joint name="wheel2_joint" type="continuous">
  <parent link="body_link"/>
  <child link="wheel2_link" />
  <origin xyz="${-s2} ${s4} ${r}" rpy="0 0 0" />
  <axis xyz="0 1 0"/>
  <limit effort="100" velocity="10"/>
  <dynamics damping="1.0" friction="1.0"/>
</joint>

<link name="wheel2_link">
  <visual>
    <origin rpy="1.570795 0 0" xyz="0 0 0"/>
    <geometry>
      <cylinder length="${d}" radius="${r}"/>
    </geometry>
  </visual>

  <collision>
    <origin rpy="1.570795 0 0" xyz="0 0 0"/>
    <geometry>
      <cylinder length="${d}" radius="${r}"/>
    </geometry>
  </collision>
  <xacro:inertia_wheel />
</link>

<joint name="caster_joint" type="fixed">
    <parent link="body_link"/>
    <child link="caster_link"/>
    <origin xyz="${s3} 0 ${r}" rpy="0 0 0"/>
</joint>

<link name="caster_link">
    <visual>
        <origin rpy="0 0 0" xyz="0 0 0"/>
        <geometry>
            <sphere radius="${r}" />
        </geometry>
    </visual>

    <collision>
        <origin rpy="0 0 0" xyz="0 0 0"/>
        <geometry>
            <sphere radius="${r}" />
        </geometry>
    </collision>
    <xacro:inertia_caster />
</link>

<!-- ========================= -->
<!-- LiDAR Link -->
<!-- ========================= -->

<joint name="lidar_joint" type="fixed">
    <origin xyz="0.0 0 ${b+r}" rpy="0 0 0"/>
    <parent link="body_link"/>
    <child link="lidar_link"/>
    <axis xyz="0 1 0" rpy="0 0 0"/>
</joint>

<link name='lidar_link'>
    <visual>
        <origin xyz="0 0 0.05" rpy="0 0 0"/>
        <geometry>
            <cylinder length="0.1" radius="0.1"/>
        </geometry>
    </visual>

    <collision name='collision'>
     <origin xyz="0 0 0.05" rpy="0 0 0"/>
     <geometry>
        <cylinder length="0.1" radius="0.1"/>
    </geometry>
    </collision>

    <inertial>
     <mass value="1e-6"/>
     <origin xyz="0 0 0" rpy="0 0 0"/>
     <inertia ixx="1e-6" ixy="0" ixz="0"
              iyy="1e-6" iyz="0" izz="1e-6"
      />
    </inertial>

</link>

<!-- ========================= -->
<!-- IMU Link -->
<!-- ========================= -->

<joint name="imu_joint" type="fixed">
    <parent link="body_link"/>
    <child link="imu_link"/>
    <origin xyz="0 0 ${s1 + 0.01}" rpy="0 0 0"/>
</joint>

<link name="imu_link">

    <visual>
        <origin xyz="0 0 0" rpy="0 0 0"/>
        <geometry>
            <box size="0.05 0.05 0.02"/>
        </geometry>
    </visual>

    <collision>
        <origin xyz="0 0 0" rpy="0 0 0"/>
        <geometry>
            <box size="0.05 0.05 0.02"/>
        </geometry>
    </collision>

    <inertial>
        <mass value="0.001"/>
        <origin xyz="0 0 0" rpy="0 0 0"/>
        <inertia
            ixx="1e-6"
            ixy="0"
            ixz="0"
            iyy="1e-6"
            iyz="0"
            izz="1e-6"/>
    </inertial>

</link>

</robot>
